Workbook

Sheet TermCOMP
B1: Benchmarks | C1: VBS | D1: Athena timout: 900s semantic-augmentor-mode=none type-annotator-mode=none signedness-info=none unreachable-exit=true muval-mode=TermCOMP | F1: PROTON | H1: AProVE | J1: UAutomizer | L1: CPAchecker | N1: 2LS | P1: MuVal
A2: AProVE_memory_alloca | B2: svcomp_a.01-alloca.c | C2: YES | D2: YES | E2: 1941 | F2: TRUE | G2: 183420 | H2: YES | I2: 70581 | J2: ERROR | K2: 13561 | L2: UNKNOWN | M2: 9285 | N2: error | O2: 280 | P2: NO | Q2: 947 | R2: Pointer
B3: svcomp_a.04-alloca.c | C3: YES | D3: YES | E3: 441 | F3: TRUE | G3: 64225 | H3: YES | I3: 6584 | J3: TRUE | K3: 4165 | L3: UNKNOWN | M3: 8070 | N3: error | O3: 292 | P3: NO | Q3: 708 | R3: Pointer
B4: svcomp_a.05-alloca.c | C4: YES | D4: YES | E4: 403 | F4: TRUE | G4: 59158 | H4: YES | I4: 6566 | J4: TRUE | K4: 3968 | L4: UNKNOWN | M4: 8084 | N4: error | O4: 282 | P4: NO | Q4: 858 | R4: Pointer
B5: svcomp_a.06-alloca.c | C5: YES | D5: YES | E5: 418 | F5: TRUE | G5: 66098 | H5: YES | I5: 9094 | J5: TRUE | K5: 4975 | L5: UNKNOWN | M5: 9596 | N5: error | O5: 265 | P5: NO | Q5: 812 | R5: Pointer
B6: svcomp_a.07-alloca.c | C6: YES | D6: YES | E6: 439 | F6: TRUE | G6: 61116 | H6: YES | I6: 9095 | J6: TRUE | K6: 5063 | L6: UNKNOWN | M6: 9690 | N6: error | O6: 271 | P6: NO | Q6: 855 | R6: Pointer
B7: svcomp_a.08-alloca.c | C7: YES | D7: YES | E7: 442 | F7: TRUE | G7: 65696 | H7: YES | I7: 7122 | J7: TRUE | K7: 4288 | L7: UNKNOWN | M7: 8207 | N7: error | O7: 276 | P7: NO | Q7: 663 | R7: Pointer
B8: svcomp_a.09_assume-alloca.c | C8: YES | D8: YES | E8: 430 | F8: FALSE | G8: 4657 | H8: YES | I8: 6888 | J8: TRUE | K8: 4536 | L8: UNKNOWN | M8: 8313 | N8: error | O8: 265 | P8: NO | Q8: 760 | R8: Pointer
B9: svcomp_a.10-alloca.c | C9: YES | D9: YES | E9: 1452 | F9: TRUE | G9: 88589 | H9: TIMEOUT | I9: 900144 | J9: ERROR | K9: 9694 | L9: UNKNOWN | M9: 8117 | N9: error | O9: 250 | P9: NO | Q9: 784 | R9: Pointer
B10: svcomp_add_last_alloca.c | C10: YES | D10: YES | E10: 1334 | F10: FALSE | G10: 2159 | H10: MAYBE | I10: 4343 | J10: TRUE | K10: 3205 | L10: UNKNOWN | M10: 6461 | N10: error | O10: 262 | P10: ERROR | Q10: 394 | R10: Pointer
B11: svcomp_array01_alloca.c | C11: YES | D11: YES | E11: 1258 | F11: INCONCLUSIVE | G11: 301865 | H11: YES | I11: 24325 | J11: TRUE | K11: 4926 | L11: UNKNOWN | M11: 7013 | N11: error | O11: 270 | P11: NO | Q11: 1012 | R11: Pointer
B12: svcomp_array02_alloca.c | C12: YES | D12: YES | E12: 181212 | F12: INCONCLUSIVE | G12: 301920 | H12: YES | I12: 79838 | J12: TRUE | K12: 6887 | L12: UNKNOWN | M12: 7539 | N12: error | O12: 298 | P12: NO | Q12: 1304 | R12: Pointer
B13: svcomp_array03_alloca.c | C13: YES | D13: YES | E13: 1899 | F13: INCONCLUSIVE | G13: 121906 | H13: TIMEOUT | I13: 910026 | J13: TRUE | K13: 8101 | L13: UNKNOWN | M13: 7030 | N13: error | O13: 288 | P13: NO | Q13: 1478 | R13: Pointer
B14: svcomp_Avery-2006FLOPS-Tabel1_true-alloca.c | C14: YES | D14: YES | E14: 440 | F14: TRUE | G14: 182879 | H14: YES | I14: 12540 | J14: TRUE | K14: 7785 | L14: UNKNOWN | M14: 10179 | N14: error | O14: 264 | P14: NO | Q14: 975 | R14: Pointer
B15: svcomp_aviad_true-alloca.c | C15: YES | D15: YES | E15: 417 | F15: TRUE | G15: 84440 | H15: TIMEOUT | I15: 910041 | J15: ERROR | K15: 18071 | L15: UNKNOWN | M15: 9595 | N15: error | O15: 272 | P15: NO | Q15: 1051 | R15: Pointer
B16: svcomp_b.01-alloca.c | C16: YES | D16: YES | E16: 436 | F16: TRUE | G16: 63536 | H16: YES | I16: 7832 | J16: TRUE | K16: 4138 | L16: UNKNOWN | M16: 8117 | N16: error | O16: 262 | P16: NO | Q16: 790 | R16: Pointer
B17: svcomp_b.02-alloca.c | C17: YES | D17: YES | E17: 443 | F17: TRUE | G17: 60030 | H17: YES | I17: 7283 | J17: TRUE | K17: 4191 | L17: UNKNOWN | M17: 8096 | N17: error | O17: 272 | P17: NO | Q17: 794 | R17: Pointer
B18: svcomp_b.03_assume-alloca.c | C18: YES | D18: YES | E18: 420 | F18: TRUE | G18: 183326 | H18: YES | I18: 6628 | J18: TRUE | K18: 3673 | L18: UNKNOWN | M18: 7301 | N18: error | O18: 274 | P18: NO | Q18: 899 | R18: Pointer
B19: svcomp_b.03-no-inv_assume-alloca.c | C19: YES | D19: YES | E19: 421 | F19: TRUE | G19: 183265 | H19: YES | I19: 6760 | J19: TRUE | K19: 3655 | L19: UNKNOWN | M19: 7311 | N19: error | O19: 273 | P19: NO | Q19: 707 | R19: Pointer
B20: svcomp_b.04-alloca.c | C20: YES | D20: YES | E20: 432 | F20: TRUE | G20: 65158 | H20: YES | I20: 3375 | J20: TRUE | K20: 4134 | L20: UNKNOWN | M20: 8215 | N20: error | O20: 289 | P20: NO | Q20: 698 | R20: Pointer
B21: svcomp_b.05-alloca.c | C21: YES | D21: YES | E21: 522 | F21: TRUE | G21: 182563 | H21: YES | I21: 6132 | J21: TRUE | K21: 3678 | L21: UNKNOWN | M21: 7328 | N21: error | O21: 286 | P21: ERROR | Q21: 450 | R21: Pointer
B22: svcomp_b.06-alloca.c | C22: YES | D22: YES | E22: 424 | F22: TRUE | G22: 63066 | H22: YES | I22: 8555 | J22: TRUE | K22: 3983 | L22: UNKNOWN | M22: 8153 | N22: error | O22: 269 | P22: NO | Q22: 864 | R22: Pointer
B23: svcomp_b.07-alloca.c | C23: YES | D23: YES | E23: 426 | F23: TRUE | G23: 60177 | H23: YES | I23: 9461 | J23: TRUE | K23: 4838 | L23: UNKNOWN | M23: 9425 | N23: error | O23: 279 | P23: NO | Q23: 824 | R23: Pointer
B24: svcomp_b.09_assume-alloca.c | C24: YES | D24: YES | E24: 443 | F24: TRUE | G24: 182551 | H24: YES | I24: 10717 | J24: TRUE | K24: 21329 | L24: UNKNOWN | M24: 8394 | N24: error | O24: 296 | P24: NO | Q24: 1082 | R24: Pointer
B25: svcomp_b.09-no-inv_assume-alloca.c | C25: YES | D25: YES | E25: 751 | F25: TRUE | G25: 79655 | H25: YES | I25: 10921 | J25: UNKNOWN | K25: 27786 | L25: UNKNOWN | M25: 8582 | N25: error | O25: 279 | P25: NO | Q25: 1085 | R25: Pointer
B26: svcomp_b.10-alloca.c | C26: YES | D26: YES | E26: 411 | F26: TRUE | G26: 110583 | H26: YES | I26: 12585 | J26: TRUE | K26: 5978 | L26: UNKNOWN | M26: 8221 | N26: error | O26: 275 | P26: NO | Q26: 800 | R26: Pointer
B27: svcomp_b.11-alloca.c | C27: YES | D27: YES | E27: 403 | F27: TRUE | G27: 112376 | H27: TIMEOUT | I27: 900153 | J27: ERROR | K27: 9532 | L27: UNKNOWN | M27: 8251 | N27: error | O27: 266 | P27: NO | Q27: 989 | R27: Pointer
B28: svcomp_b.12-alloca.c | C28: YES | D28: YES | E28: 694 | F28: TRUE | G28: 109403 | H28: YES | I28: 11005 | J28: TRUE | K28: 6893 | L28: UNKNOWN | M28: 8122 | N28: error | O28: 264 | P28: NO | Q28: 6693 | R28: Pointer
B29: svcomp_b.13-alloca.c | C29: YES | D29: YES | E29: 7215 | F29: TRUE | G29: 93045 | H29: YES | I29: 22322 | J29: ERROR | K29: 33383 | L29: UNKNOWN | M29: 9436 | N29: error | O29: 270 | P29: NO | Q29: 42146 | R29: Pointer
B30: svcomp_b.14-alloca.c | C30: YES | D30: YES | E30: 1192 | F30: TRUE | G30: 183496 | H30: YES | I30: 7536 | J30: TRUE | K30: 9009 | L30: UNKNOWN | M30: 9504 | N30: error | O30: 261 | P30: NO | Q30: 785 | R30: Pointer
B31: svcomp_b.15-alloca.c | C31: YES | D31: YES | E31: 1649 | F31: TRUE | G31: 184414 | H31: YES | I31: 8312 | J31: ERROR | K31: 112373 | L31: UNKNOWN | M31: 11864 | N31: error | O31: 270 | P31: NO | Q31: 915 | R31: Pointer
B32: svcomp_b.16-alloca.c | C32: YES | D32: YES | E32: 2714 | F32: TRUE | G32: 183181 | H32: YES | I32: 10575 | J32: TRUE | K32: 7153 | L32: UNKNOWN | M32: 9276 | N32: error | O32: 270 | P32: NO | Q32: 732 | R32: Pointer
B33: svcomp_b.17-alloca.c | C33: YES | D33: YES | E33: 7261 | F33: TRUE | G33: 184569 | H33: ERROR | I33: 71562 | J33: ERROR | K33: 11355 | L33: UNKNOWN | M33: 11410 | N33: error | O33: 268 | P33: NO | Q33: 1039 | R33: Pointer
B34: svcomp_b.18-alloca.c | C34: YES | D34: TIMEOUT | E34: 900709 | F34: TRUE | G34: 182735 | H34: YES | I34: 6353 | J34: TRUE | K34: 8712 | L34: UNKNOWN | M34: 8734 | N34: error | O34: 263 | P34: ERROR | Q34: 661 | R34: Pointer
B35: svcomp_Ben-Amram-2010LMCS-Ex2.3_true-alloca.c | C35: YES | D35: YES | E35: 1390 | F35: TRUE | G35: 183396 | H35: YES | I35: 9711 | J35: TRUE | K35: 11148 | L35: UNKNOWN | M35: 8024 | N35: error | O35: 271 | P35: NO | Q35: 922 | R35: Pointer
B36: svcomp_BradleyMannaSipma-2005CAV-Fig1_true-alloca.c | C36: YES | D36: TIMEOUT | E36: 900432 | F36: TRUE | G36: 183549 | H36: TIMEOUT | I36: 910031 | J36: TRUE | K36: 4796 | L36: UNKNOWN | M36: 8483 | N36: error | O36: 299 | P36: NO | Q36: 1436 | R36: Pointer
B37: svcomp_BradleyMannaSipma-2005CAV-Fig1-modified_false-termination.c | C37: NO | D37: NO | E37: 520 | F37: INCONCLUSIVE | G37: 121817 | H37: MAYBE | I37: 74882 | J37: FALSE | K37: 2955 | L37: UNKNOWN | M37: 7508 | N37: error | O37: 279 | P37: NO | Q37: 951 | R37: Pointer
B38: svcomp_BradleyMannaSipma-2005ICALP-Fig1_true-alloca.c | C38: NO | D38: NO | E38: 416 | F38: FALSE | G38: 2233 | H38: MAYBE | I38: 14752 | J38: FALSE | K38: 2720 | L38: UNKNOWN | M38: 7304 | N38: error | O38: 284 | P38: NO | Q38: 1061 | R38: Pointer
B39: svcomp_BrockschmidtCookFuhs-2013CAV-Fig1_true-alloca.c | C39: YES | D39: YES | E39: 1456 | F39: INCONCLUSIVE | G39: 302146 | H39: YES | I39: 10597 | J39: ERROR | K39: 8370 | L39: UNKNOWN | M39: 8728 | N39: error | O39: 273 | P39: NO | Q39: 997 | R39: Pointer
B40: svcomp_BrockschmidtCookFuhs-2013CAV-Introduction_true-alloca.c | C40: YES | D40: YES | E40: 643 | F40: INCONCLUSIVE | G40: 175113 | H40: YES | I40: 5772 | J40: TRUE | K40: 3560 | L40: UNKNOWN | M40: 6885 | N40: error | O40: 263 | P40: NO | Q40: 734 | R40: Pointer
...

Sheet FSE
B1: Benchmarks | C1: Athena_BV (Bitvector Mode) timout: 600s semantic-augmentor-mode=none type-annotator-mode=all signedness-info=all unreachable-exit=true muval-mode=FSE-BV | E1: Athena_MA (Modulo Arithmetic Mode) timout: 300s semantic-augmentor-mode=only-nobv type-annotator-mode=only-bv signedness-info=only-bv unreachable-exit=true muval-mode=FSE-MI | G1: Athena_MI (Mathematical Integer Mode) timout: 270s semantic-augmentor-mode=none type-annotator-mode=all signedness-info=all unreachable-exit=true muval-mode=FSE-MI | I1: CPAchecker: Underflow/Overflow? timout: 30s | K1: Athena_MA + Athena_MI & CPAchecker timout: 600s | M1: Athena (Athena_BV + [Athena_MA + Athema_MI + CPAchecker]) timout: 1200s | O1: PROTON | Q1: AProVE | S1: UAutomizer | U1: CPAchecker | W1: 2LS | Y1: MuVal
A2: loop | B2: Adding_Subtracting_Zero_1_NT.c | C2: NO | D2: 735 | E2: NO | F2: 2458 | G2: NO | H2: 366 | I2: TRUE | J2: 5352 | K2: =IF(OR(E2="NO", E2="YES"), E2, IF(I2=FALSE, G2, E2)) -> NO | L2: =IF(OR(E2="NO", E2="YES"), F2, IF(I2=FALSE, SUM(F2, J2, H2), SUM(F2, J2))) -> 2458 | M2: =IF(OR(C2="NO", C2="YES"), C2, IF(OR(K2="NO", K2="YES"), K2, C2)) -> NO | N2: =IF(OR(C2="NO", C2="YES"), D2, IF(OR(K2="NO", K2="YES"), SUM(D2, L2), SUM(D2, L2))) -> 735 | O2: FALSE | P2: 3138 | Q2: NO | R2: 6515 | S2: FALSE | T2: 3936 | U2: UNKNOWN | V2: 1201407 | W2: unknown | X2: 546 | Y2: NO | Z2: 567
B3: Adding_Subtracting_Zero_1_T.c | C3: YES | D3: 557 | E3: YES | F3: 2558 | G3: YES | H3: 394 | I3: TRUE | J3: 4507 | K3: =IF(OR(E3="NO", E3="YES"), E3, IF(I3=FALSE, G3, E3)) -> YES | L3: =IF(OR(E3="NO", E3="YES"), F3, IF(I3=FALSE, SUM(F3, J3, H3), SUM(F3, J3))) -> 2558 | M3: =IF(OR(C3="NO", C3="YES"), C3, IF(OR(K3="NO", K3="YES"), K3, C3)) -> YES | N3: =IF(OR(C3="NO", C3="YES"), D3, IF(OR(K3="NO", K3="YES"), SUM(D3, L3), SUM(D3, L3))) -> 557 | O3: TRUE | P3: 182292 | Q3: YES | R3: 5683 | S3: TRUE | T3: 3679 | U3: UNKNOWN | V3: 5875 | W3: yes | X3: 316 | Y3: YES | Z3: 380
B4: Adding_Subtracting_Zero_2_NT.c | C4: NO | D4: 93989 | E4: NO | F4: 14124 | G4: NO | H4: 492 | I4: FALSE | J4: 5131 | K4: =IF(OR(E4="NO", E4="YES"), E4, IF(I4=FALSE, G4, E4)) -> NO | L4: =IF(OR(E4="NO", E4="YES"), F4, IF(I4=FALSE, SUM(F4, J4, H4), SUM(F4, J4))) -> 14124 | M4: =IF(OR(C4="NO", C4="YES"), C4, IF(OR(K4="NO", K4="YES"), K4, C4)) -> NO | N4: =IF(OR(C4="NO", C4="YES"), D4, IF(OR(K4="NO", K4="YES"), SUM(D4, L4), SUM(D4, L4))) -> 93989 | O4: FALSE | P4: 2072 | Q4: MAYBE | R4: 15825 | S4: TIMEOUT | T4: 1200346 | U4: UNKNOWN | V4: 7158 | W4: unknown | X4: 513 | Y4: NO | Z4: 358
B5: Adding_Subtracting_Zero_2_T.c | C5: TIMEOUT | D5: 600412 | E5: TIMEOUT | F5: 300389 | G5: YES | H5: 586 | I5: FALSE | J5: 5156 | K5: =IF(OR(E5="NO", E5="YES"), E5, IF(I5=FALSE, G5, E5)) -> YES | L5: =IF(OR(E5="NO", E5="YES"), F5, IF(I5=FALSE, SUM(F5, J5, H5), SUM(F5, J5))) -> 306131 | M5: =IF(OR(C5="NO", C5="YES"), C5, IF(OR(K5="NO", K5="YES"), K5, C5)) -> YES | N5: =IF(OR(C5="NO", C5="YES"), D5, IF(OR(K5="NO", K5="YES"), SUM(D5, L5), SUM(D5, L5))) -> 906543 | O5: TRUE | P5: 182519 | Q5: YES | R5: 25672 | S5: TIMEOUT | T5: 1200404 | U5: UNKNOWN | V5: 7079 | W5: unknown | X5: 503 | Y5: YES | Z5: 1391
B6: Adding_Subtracting_Zero_3_NT.c | C6: TIMEOUT | D6: 600535 | E6: TIMEOUT | F6: 300793 | G6: NO | H6: 106195 | I6: FALSE | J6: 4894 | K6: =IF(OR(E6="NO", E6="YES"), E6, IF(I6=FALSE, G6, E6)) -> NO | L6: =IF(OR(E6="NO", E6="YES"), F6, IF(I6=FALSE, SUM(F6, J6, H6), SUM(F6, J6))) -> 411882 | M6: =IF(OR(C6="NO", C6="YES"), C6, IF(OR(K6="NO", K6="YES"), K6, C6)) -> NO | N6: =IF(OR(C6="NO", C6="YES"), D6, IF(OR(K6="NO", K6="YES"), SUM(D6, L6), SUM(D6, L6))) -> 1012417 | O6: FALSE | P6: 3016 | Q6: ERROR | R6: 897970 | S6: ERROR | T6: 19464 | U6: TIMEOUT | V6: 1211741 | W6: unknown | X6: 451 | Y6: TIMEOUT | Z6: 1210035
B7: Adding_Subtracting_Zero_3_T.c | C7: TIMEOUT | D7: 600536 | E7: TIMEOUT | F7: 301856 | G7: TIMEOUT | H7: 270311 | I7: FALSE | J7: 4866 | K7: =IF(OR(E7="NO", E7="YES"), E7, IF(I7=FALSE, G7, E7)) -> TIMEOUT | L7: =IF(OR(E7="NO", E7="YES"), F7, IF(I7=FALSE, SUM(F7, J7, H7), SUM(F7, J7))) -> 577033 | M7: =IF(OR(C7="NO", C7="YES"), C7, IF(OR(K7="NO", K7="YES"), K7, C7)) -> TIMEOUT | N7: =IF(OR(C7="NO", C7="YES"), D7, IF(OR(K7="NO", K7="YES"), SUM(D7, L7), SUM(D7, L7))) -> 1177569 | O7: TRUE | P7: 185536 | Q7: TIMEOUT | R7: 1210066 | S7: TRUE | T7: 36735 | U7: UNKNOWN | V7: 1202220 | W7: unknown | X7: 573 | Y7: TIMEOUT | Z7: 1210039
B8: Adding_Subtracting_Zero_4_NT.c | C8: NO | D8: 38140 | E8: TIMEOUT | F8: 301253 | G8: NO | H8: 11137 | I8: FALSE | J8: 4708 | K8: =IF(OR(E8="NO", E8="YES"), E8, IF(I8=FALSE, G8, E8)) -> NO | L8: =IF(OR(E8="NO", E8="YES"), F8, IF(I8=FALSE, SUM(F8, J8, H8), SUM(F8, J8))) -> 317098 | M8: =IF(OR(C8="NO", C8="YES"), C8, IF(OR(K8="NO", K8="YES"), K8, C8)) -> NO | N8: =IF(OR(C8="NO", C8="YES"), D8, IF(OR(K8="NO", K8="YES"), SUM(D8, L8), SUM(D8, L8))) -> 38140 | O8: FALSE | P8: 3993 | Q8: TIMEOUT | R8: 1210042 | S8: ERROR | T8: 11394 | U8: ERROR | V8: 16279 | W8: unknown | X8: 508 | Y8: NO | Z8: 1329
B9: Adding_Subtracting_Zero_4_T.c | C9: TIMEOUT | D9: 600599 | E9: TIMEOUT | F9: 301052 | G9: TIMEOUT | H9: 270250 | I9: FALSE | J9: 4723 | K9: =IF(OR(E9="NO", E9="YES"), E9, IF(I9=FALSE, G9, E9)) -> TIMEOUT | L9: =IF(OR(E9="NO", E9="YES"), F9, IF(I9=FALSE, SUM(F9, J9, H9), SUM(F9, J9))) -> 576025 | M9: =IF(OR(C9="NO", C9="YES"), C9, IF(OR(K9="NO", K9="YES"), K9, C9)) -> TIMEOUT | N9: =IF(OR(C9="NO", C9="YES"), D9, IF(OR(K9="NO", K9="YES"), SUM(D9, L9), SUM(D9, L9))) -> 1176624 | O9: TRUE | P9: 185246 | Q9: YES | R9: 39874 | S9: TRUE | T9: 5341 | U9: ERROR | V9: 15943 | W9: yes | X9: 618 | Y9: TIMEOUT | Z9: 1210028
B10: Adding_Subtracting_Zero_5_NT.c | C10: NO | D10: 818 | E10: NO | F10: 10815 | G10: NO | H10: 487 | I10: TIMEOUT | J10: 3773 | K10: =IF(OR(E10="NO", E10="YES"), E10, IF(I10=FALSE, G10, E10)) -> NO | L10: =IF(OR(E10="NO", E10="YES"), F10, IF(I10=FALSE, SUM(F10, J10, H10), SUM(F10, J10))) -> 10815 | M10: =IF(OR(C10="NO", C10="YES"), C10, IF(OR(K10="NO", K10="YES"), K10, C10)) -> NO | N10: =IF(OR(C10="NO", C10="YES"), D10, IF(OR(K10="NO", K10="YES"), SUM(D10, L10), SUM(D10, L10))) -> 818 | O10: FALSE | P10: 2327 | Q10: MAYBE | R10: 7389 | S10: FALSE | T10: 3802 | U10: ERROR | V10: 3827 | W10: unknown | X10: 501 | Y10: ERROR | Z10: 355 | AA10: Pointer + Structure
B11: Adding_Subtracting_Zero_5_T.c | C11: TIMEOUT | D11: 600456 | E11: TIMEOUT | F11: 300540 | G11: TIMEOUT | H11: 270249 | I11: TIMEOUT | J11: 3736 | K11: =IF(OR(E11="NO", E11="YES"), E11, IF(I11=FALSE, G11, E11)) -> TIMEOUT | L11: =IF(OR(E11="NO", E11="YES"), F11, IF(I11=FALSE, SUM(F11, J11, H11), SUM(F11, J11))) -> 304276 | M11: =IF(OR(C11="NO", C11="YES"), C11, IF(OR(K11="NO", K11="YES"), K11, C11)) -> TIMEOUT | N11: =IF(OR(C11="NO", C11="YES"), D11, IF(OR(K11="NO", K11="YES"), SUM(D11, L11), SUM(D11, L11))) -> 904732 | O11: FALSE | P11: 2206 | Q11: MAYBE | R11: 7223 | S11: TIMEOUT | T11: 1200323 | U11: ERROR | V11: 3858 | W11: unknown | X11: 528 | Y11: ERROR | Z11: 347 | AA11: Pointer + Structure
B12: Incorrect_Bit_Calculation_1_NT.c | C12: NO | D12: 468 | E12: ERROR | F12: 330 | G12: ERROR | H12: 263 | I12: TRUE | J12: 4191 | K12: =IF(OR(E12="NO", E12="YES"), E12, IF(I12=FALSE, G12, E12)) -> ERROR | L12: =IF(OR(E12="NO", E12="YES"), F12, IF(I12=FALSE, SUM(F12, J12, H12), SUM(F12, J12))) -> 4521 | M12: =IF(OR(C12="NO", C12="YES"), C12, IF(OR(K12="NO", K12="YES"), K12, C12)) -> NO | N12: =IF(OR(C12="NO", C12="YES"), D12, IF(OR(K12="NO", K12="YES"), SUM(D12, L12), SUM(D12, L12))) -> 468 | O12: FALSE | P12: 2017 | Q12: MAYBE | R12: 2557 | S12: UNKNOWN | T12: 4945 | U12: UNKNOWN | V12: 1201201 | W12: unknown | X12: 266 | Y12: NO | Z12: 432 | AA12: Bit Calculation
B13: Incorrect_Bit_Calculation_1_T.c | C13: YES | D13: 453 | E13: ERROR | F13: 284 | G13: ERROR | H13: 245 | I13: TRUE | J13: 4176 | K13: =IF(OR(E13="NO", E13="YES"), E13, IF(I13=FALSE, G13, E13)) -> ERROR | L13: =IF(OR(E13="NO", E13="YES"), F13, IF(I13=FALSE, SUM(F13, J13, H13), SUM(F13, J13))) -> 4460 | M13: =IF(OR(C13="NO", C13="YES"), C13, IF(OR(K13="NO", K13="YES"), K13, C13)) -> YES | N13: =IF(OR(C13="NO", C13="YES"), D13, IF(OR(K13="NO", K13="YES"), SUM(D13, L13), SUM(D13, L13))) -> 453 | O13: TRUE | P13: 42258 | Q13: MAYBE | R13: 2526 | S13: TRUE | T13: 2739 | U13: UNKNOWN | V13: 1201077 | W13: yes | X13: 289 | Y13: NO | Z13: 413 | AA13: Bit Calculation
B14: Incorrect_Bit_Calculation_2_NT.c | C14: NO | D14: 425 | E14: ERROR | F14: 297 | G14: ERROR | H14: 252 | I14: FALSE | J14: 4479 | K14: =IF(OR(E14="NO", E14="YES"), E14, IF(I14=FALSE, G14, E14)) -> ERROR | L14: =IF(OR(E14="NO", E14="YES"), F14, IF(I14=FALSE, SUM(F14, J14, H14), SUM(F14, J14))) -> 5028 | M14: =IF(OR(C14="NO", C14="YES"), C14, IF(OR(K14="NO", K14="YES"), K14, C14)) -> NO | N14: =IF(OR(C14="NO", C14="YES"), D14, IF(OR(K14="NO", K14="YES"), SUM(D14, L14), SUM(D14, L14))) -> 425 | O14: FALSE | P14: 2022 | Q14: MAYBE | R14: 2635 | S14: UNKNOWN | T14: 3879 | U14: UNKNOWN | V14: 1201048 | W14: unknown | X14: 489 | Y14: NO | Z14: 442 | AA14: Bit Calculation
B15: Incorrect_Bit_Calculation_2_T.c | C15: YES | D15: 12338 | E15: ERROR | F15: 321 | G15: ERROR | H15: 247 | I15: FALSE | J15: 4497 | K15: =IF(OR(E15="NO", E15="YES"), E15, IF(I15=FALSE, G15, E15)) -> ERROR | L15: =IF(OR(E15="NO", E15="YES"), F15, IF(I15=FALSE, SUM(F15, J15, H15), SUM(F15, J15))) -> 5065 | M15: =IF(OR(C15="NO", C15="YES"), C15, IF(OR(K15="NO", K15="YES"), K15, C15)) -> YES | N15: =IF(OR(C15="NO", C15="YES"), D15, IF(OR(K15="NO", K15="YES"), SUM(D15, L15), SUM(D15, L15))) -> 12338 | O15: TRUE | P15: 49955 | Q15: MAYBE | R15: 2731 | S15: UNKNOWN | T15: 3898 | U15: UNKNOWN | V15: 1201162 | W15: unknown | X15: 438 | Y15: NO | Z15: 414 | AA15: Bit Calculation
B16: Incorrect_Bit_Calculation_3_NT.c | C16: NO | D16: 452 | E16: ERROR | F16: 341 | G16: ERROR | H16: 259 | I16: TRUE | J16: 4239 | K16: =IF(OR(E16="NO", E16="YES"), E16, IF(I16=FALSE, G16, E16)) -> ERROR | L16: =IF(OR(E16="NO", E16="YES"), F16, IF(I16=FALSE, SUM(F16, J16, H16), SUM(F16, J16))) -> 4580 | M16: =IF(OR(C16="NO", C16="YES"), C16, IF(OR(K16="NO", K16="YES"), K16, C16)) -> NO | N16: =IF(OR(C16="NO", C16="YES"), D16, IF(OR(K16="NO", K16="YES"), SUM(D16, L16), SUM(D16, L16))) -> 452 | O16: FALSE | P16: 2034 | Q16: MAYBE | R16: 2474 | S16: FALSE | T16: 2179 | U16: UNKNOWN | V16: 5102 | W16: unknown | X16: 322 | Y16: NO | Z16: 408 | AA16: Bit Calculation
B17: Incorrect_Bit_Calculation_3_T.c | C17: YES | D17: 418 | E17: ERROR | F17: 326 | G17: ERROR | H17: 262 | I17: TRUE | J17: 4244 | K17: =IF(OR(E17="NO", E17="YES"), E17, IF(I17=FALSE, G17, E17)) -> ERROR | L17: =IF(OR(E17="NO", E17="YES"), F17, IF(I17=FALSE, SUM(F17, J17, H17), SUM(F17, J17))) -> 4570 | M17: =IF(OR(C17="NO", C17="YES"), C17, IF(OR(K17="NO", K17="YES"), K17, C17)) -> YES | N17: =IF(OR(C17="NO", C17="YES"), D17, IF(OR(K17="NO", K17="YES"), SUM(D17, L17), SUM(D17, L17))) -> 418 | O17: TRUE | P17: 59675 | Q17: MAYBE | R17: 2552 | S17: UNKNOWN | T17: 3839 | U17: UNKNOWN | V17: 5235 | W17: unknown | X17: 367 | Y17: NO | Z17: 397 | AA17: Bit Calculation
B18: Incorrect_Control_Statement_1_NT.c | C18: TIMEOUT | D18: 600339 | E18: TIMEOUT | F18: 300413 | G18: TIMEOUT | H18: 270253 | I18: TRUE | J18: 4712 | K18: =IF(OR(E18="NO", E18="YES"), E18, IF(I18=FALSE, G18, E18)) -> TIMEOUT | L18: =IF(OR(E18="NO", E18="YES"), F18, IF(I18=FALSE, SUM(F18, J18, H18), SUM(F18, J18))) -> 305125 | M18: =IF(OR(C18="NO", C18="YES"), C18, IF(OR(K18="NO", K18="YES"), K18, C18)) -> TIMEOUT | N18: =IF(OR(C18="NO", C18="YES"), D18, IF(OR(K18="NO", K18="YES"), SUM(D18, L18), SUM(D18, L18))) -> 905464 | O18: INCONCLUSIVE | P18: 302173 | Q18: MAYBE | R18: 13693 | S18: TIMEOUT | T18: 1200323 | U18: UNKNOWN | V18: 413225 | W18: unknown | X18: 369 | Y18: NO | Z18: 3037 | AA18: Pointer + Array
B19: Incorrect_Control_Statement_1_T.c | C19: TIMEOUT | D19: 600426 | E19: TIMEOUT | F19: 300477 | G19: TIMEOUT | H19: 270312 | I19: TRUE | J19: 4765 | K19: =IF(OR(E19="NO", E19="YES"), E19, IF(I19=FALSE, G19, E19)) -> TIMEOUT | L19: =IF(OR(E19="NO", E19="YES"), F19, IF(I19=FALSE, SUM(F19, J19, H19), SUM(F19, J19))) -> 305242 | M19: =IF(OR(C19="NO", C19="YES"), C19, IF(OR(K19="NO", K19="YES"), K19, C19)) -> TIMEOUT | N19: =IF(OR(C19="NO", C19="YES"), D19, IF(OR(K19="NO", K19="YES"), SUM(D19, L19), SUM(D19, L19))) -> 905668 | O19: TRUE | P19: 193913 | Q19: TIMEOUT | R19: 1200271 | S19: TIMEOUT | T19: 1200368 | U19: UNKNOWN | V19: 420230 | W19: unknown | X19: 371 | Y19: NO | Z19: 276850 | AA19: Pointer + Array
B20: Incorrect_Control_Statement_2_NT.c | C20: TIMEOUT | D20: 600394 | E20: TIMEOUT | F20: 300462 | G20: TIMEOUT | H20: 270303 | I20: TRUE | J20: 4562 | K20: =IF(OR(E20="NO", E20="YES"), E20, IF(I20=FALSE, G20, E20)) -> TIMEOUT | L20: =IF(OR(E20="NO", E20="YES"), F20, IF(I20=FALSE, SUM(F20, J20, H20), SUM(F20, J20))) -> 305024 | M20: =IF(OR(C20="NO", C20="YES"), C20, IF(OR(K20="NO", K20="YES"), K20, C20)) -> TIMEOUT | N20: =IF(OR(C20="NO", C20="YES"), D20, IF(OR(K20="NO", K20="YES"), SUM(D20, L20), SUM(D20, L20))) -> 905418 | O20: FALSE | P20: 4367 | Q20: MAYBE | R20: 14825 | S20: FALSE | T20: 35905 | U20: UNKNOWN | V20: 10463 | W20: unknown | X20: 390 | Y20: NO | Z20: 1848 | AA20: Array
B21: Incorrect_Control_Statement_2_T.c | C21: YES | D21: 772 | E21: YES | F21: 4864 | G21: YES | H21: 511 | I21: TRUE | J21: 4650 | K21: =IF(OR(E21="NO", E21="YES"), E21, IF(I21=FALSE, G21, E21)) -> YES | L21: =IF(OR(E21="NO", E21="YES"), F21, IF(I21=FALSE, SUM(F21, J21, H21), SUM(F21, J21))) -> 4864 | M21: =IF(OR(C21="NO", C21="YES"), C21, IF(OR(K21="NO", K21="YES"), K21, C21)) -> YES | N21: =IF(OR(C21="NO", C21="YES"), D21, IF(OR(K21="NO", K21="YES"), SUM(D21, L21), SUM(D21, L21))) -> 772 | O21: TRUE | P21: 8537 | Q21: YES | R21: 15710 | S21: TRUE | T21: 18183 | U21: UNKNOWN | V21: 10257 | W21: yes | X21: 371 | Y21: TIMEOUT | Z21: 1210031 | AA21: Array
B22: Incorrect_Initialization_1_NT.c | C22: NO | D22: 377608 | E22: TIMEOUT | F22: 300418 | G22: TIMEOUT | H22: 270295 | I22: TRUE | J22: 4854 | K22: =IF(OR(E22="NO", E22="YES"), E22, IF(I22=FALSE, G22, E22)) -> TIMEOUT | L22: =IF(OR(E22="NO", E22="YES"), F22, IF(I22=FALSE, SUM(F22, J22, H22), SUM(F22, J22))) -> 305272 | M22: =IF(OR(C22="NO", C22="YES"), C22, IF(OR(K22="NO", K22="YES"), K22, C22)) -> NO | N22: =IF(OR(C22="NO", C22="YES"), D22, IF(OR(K22="NO", K22="YES"), SUM(D22, L22), SUM(D22, L22))) -> 377608 | O22: INCONCLUSIVE | P22: 301847 | Q22: MAYBE | R22: 6353 | S22: TIMEOUT | T22: 1200279 | U22: UNKNOWN | V22: 822503 | W22: unknown | X22: 337 | Y22: ERROR | Z22: 457 | AA22: Pointer + Array
B23: Incorrect_Initialization_1_T.c | C23: TIMEOUT | D23: 600432 | E23: TIMEOUT | F23: 300543 | G23: TIMEOUT | H23: 270310 | I23: TRUE | J23: 4930 | K23: =IF(OR(E23="NO", E23="YES"), E23, IF(I23=FALSE, G23, E23)) -> TIMEOUT | L23: =IF(OR(E23="NO", E23="YES"), F23, IF(I23=FALSE, SUM(F23, J23, H23), SUM(F23, J23))) -> 305473 | M23: =IF(OR(C23="NO", C23="YES"), C23, IF(OR(K23="NO", K23="YES"), K23, C23)) -> TIMEOUT | N23: =IF(OR(C23="NO", C23="YES"), D23, IF(OR(K23="NO", K23="YES"), SUM(D23, L23), SUM(D23, L23))) -> 905905 | O23: INCONCLUSIVE | P23: 301909 | Q23: MAYBE | R23: 6478 | S23: TIMEOUT | T23: 1200337 | U23: UNKNOWN | V23: 658707 | W23: unknown | X23: 356 | Y23: ERROR | Z23: 454 | AA23: Pointer + Array
B24: Incorrect_Initialization_2_NT.c | C24: NO | D24: 1122 | E24: NO | F24: 4915 | G24: NO | H24: 509 | I24: TRUE | J24: 6434 | K24: =IF(OR(E24="NO", E24="YES"), E24, IF(I24=FALSE, G24, E24)) -> NO | L24: =IF(OR(E24="NO", E24="YES"), F24, IF(I24=FALSE, SUM(F24, J24, H24), SUM(F24, J24))) -> 4915 | M24: =IF(OR(C24="NO", C24="YES"), C24, IF(OR(K24="NO", K24="YES"), K24, C24)) -> NO | N24: =IF(OR(C24="NO", C24="YES"), D24, IF(OR(K24="NO", K24="YES"), SUM(D24, L24), SUM(D24, L24))) -> 1122 | O24: FALSE | P24: 2111 | Q24: MAYBE | R24: 139336 | S24: FALSE | T24: 8626 | U24: UNKNOWN | V24: 13194 | W24: unknown | X24: 680 | Y24: NO | Z24: 1234
B25: Incorrect_Initialization_2_NT.c | C25: NO | D25: 2489 | E25: TIMEOUT | F25: 300906 | G25: NO | H25: 598 | I25: UNKNOWN | J25: 31904 | K25: =IF(OR(E25="NO", E25="YES"), E25, IF(I25=FALSE, G25, E25)) -> TIMEOUT | L25: =IF(OR(E25="NO", E25="YES"), F25, IF(I25=FALSE, SUM(F25, J25, H25), SUM(F25, J25))) -> 332810 | M25: =IF(OR(C25="NO", C25="YES"), C25, IF(OR(K25="NO", K25="YES"), K25, C25)) -> NO | N25: =IF(OR(C25="NO", C25="YES"), D25, IF(OR(K25="NO", K25="YES"), SUM(D25, L25), SUM(D25, L25))) -> 2489 | O25: FALSE | P25: 2136 | Q25: MAYBE | R25: 29300 | S25: FALSE | T25: 139167 | U25: UNKNOWN | V25: 1205086 | W25: unknown | X25: 748 | Y25: NO | Z25: 75632
B26: Incorrect_Initialization_3_NT.c | C26: TIMEOUT | D26: 600418 | E26: TIMEOUT | F26: 300466 | G26: TIMEOUT | H26: 270299 | I26: TRUE | J26: 4769 | K26: =IF(OR(E26="NO", E26="YES"), E26, IF(I26=FALSE, G26, E26)) -> TIMEOUT | L26: =IF(OR(E26="NO", E26="YES"), F26, IF(I26=FALSE, SUM(F26, J26, H26), SUM(F26, J26))) -> 305235 | M26: =IF(OR(C26="NO", C26="YES"), C26, IF(OR(K26="NO", K26="YES"), K26, C26)) -> TIMEOUT | N26: =IF(OR(C26="NO", C26="YES"), D26, IF(OR(K26="NO", K26="YES"), SUM(D26, L26), SUM(D26, L26))) -> 905653 | O26: INCONCLUSIVE | P26: 302278 | Q26: MAYBE | R26: 9071 | S26: TIMEOUT | T26: 1200294 | U26: UNKNOWN | V26: 267135 | W26: unknown | X26: 391 | Y26: NO | Z26: 549 | AA26: Pointer + Array
B27: Incorrect_Initialization_3_T.c | C27: TIMEOUT | D27: 600459 | E27: TIMEOUT | F27: 300405 | G27: TIMEOUT | H27: 270364 | I27: TRUE | J27: 4730 | K27: =IF(OR(E27="NO", E27="YES"), E27, IF(I27=FALSE, G27, E27)) -> TIMEOUT | L27: =IF(OR(E27="NO", E27="YES"), F27, IF(I27=FALSE, SUM(F27, J27, H27), SUM(F27, J27))) -> 305135 | M27: =IF(OR(C27="NO", C27="YES"), C27, IF(OR(K27="NO", K27="YES"), K27, C27)) -> TIMEOUT | N27: =IF(OR(C27="NO", C27="YES"), D27, IF(OR(K27="NO", K27="YES"), SUM(D27, L27), SUM(D27, L27))) -> 905594 | O27: INCONCLUSIVE | P27: 302106 | Q27: MAYBE | R27: 7678 | S27: TIMEOUT | T27: 1200305 | U27: UNKNOWN | V27: 266290 | W27: unknown | X27: 399 | Y27: NO | Z27: 595 | AA27: Pointer + Array
B28: Incorrect_Initialization_4_NT.c | C28: NO | D28: 5923 | E28: NO | F28: 20865 | G28: NO | H28: 461 | I28: UNKNOWN | J28: 30929 | K28: =IF(OR(E28="NO", E28="YES"), E28, IF(I28=FALSE, G28, E28)) -> NO | L28: =IF(OR(E28="NO", E28="YES"), F28, IF(I28=FALSE, SUM(F28, J28, H28), SUM(F28, J28))) -> 20865 | M28: =IF(OR(C28="NO", C28="YES"), C28, IF(OR(K28="NO", K28="YES"), K28, C28)) -> NO | N28: =IF(OR(C28="NO", C28="YES"), D28, IF(OR(K28="NO", K28="YES"), SUM(D28, L28), SUM(D28, L28))) -> 5923 | O28: FALSE | P28: 2201 | Q28: MAYBE | R28: 106323 | S28: FALSE | T28: 3294 | U28: UNKNOWN | V28: 1201010 | W28: unknown | X28: 550 | Y28: NO | Z28: 566
B29: Incorrect_Initialization_4_T.c | C29: YES | D29: 82397 | E29: TIMEOUT | F29: 300456 | G29: YES | H29: 521 | I29: UNKNOWN | J29: 30963 | K29: =IF(OR(E29="NO", E29="YES"), E29, IF(I29=FALSE, G29, E29)) -> TIMEOUT | L29: =IF(OR(E29="NO", E29="YES"), F29, IF(I29=FALSE, SUM(F29, J29, H29), SUM(F29, J29))) -> 331419 | M29: =IF(OR(C29="NO", C29="YES"), C29, IF(OR(K29="NO", K29="YES"), K29, C29)) -> YES | N29: =IF(OR(C29="NO", C29="YES"), D29, IF(OR(K29="NO", K29="YES"), SUM(D29, L29), SUM(D29, L29))) -> 82397 | O29: TRUE | P29: 182500 | Q29: YES | R29: 8395 | S29: ERROR | T29: 11450 | U29: TIMEOUT | V29: 1211747 | W29: yes | X29: 545 | Y29: YES | Z29: 983
B30: Incorrect_Update_for_Loop_Iterator_1_NT.c | C30: NO | D30: 175403 | E30: TIMEOUT | F30: 300771 | G30: NO | H30: 1515 | I30: UNKNOWN | J30: 31359 | K30: =IF(OR(E30="NO", E30="YES"), E30, IF(I30=FALSE, G30, E30)) -> TIMEOUT | L30: =IF(OR(E30="NO", E30="YES"), F30, IF(I30=FALSE, SUM(F30, J30, H30), SUM(F30, J30))) -> 332130 | M30: =IF(OR(C30="NO", C30="YES"), C30, IF(OR(K30="NO", K30="YES"), K30, C30)) -> NO | N30: =IF(OR(C30="NO", C30="YES"), D30, IF(OR(K30="NO", K30="YES"), SUM(D30, L30), SUM(D30, L30))) -> 175403 | O30: FALSE | P30: 2061 | Q30: NO | R30: 20315 | S30: FALSE | T30: 2375 | U30: UNKNOWN | V30: 1200975 | W30: unknown | X30: 450 | Y30: NO | Z30: 529 | AA30: Overflow/Underflow
B31: Incorrect_Update_for_Loop_Iterator_1_T.c | C31: YES | D31: 10760 | E31: YES | F31: 12007 | G31: YES | H31: 373 | I31: TRUE | J31: 5218 | K31: =IF(OR(E31="NO", E31="YES"), E31, IF(I31=FALSE, G31, E31)) -> YES | L31: =IF(OR(E31="NO", E31="YES"), F31, IF(I31=FALSE, SUM(F31, J31, H31), SUM(F31, J31))) -> 12007 | M31: =IF(OR(C31="NO", C31="YES"), C31, IF(OR(K31="NO", K31="YES"), K31, C31)) -> YES | N31: =IF(OR(C31="NO", C31="YES"), D31, IF(OR(K31="NO", K31="YES"), SUM(D31, L31), SUM(D31, L31))) -> 10760 | O31: TRUE | P31: 117565 | Q31: YES | R31: 3458 | S31: TRUE | T31: 5640 | U31: TRUE | V31: 18126 | W31: unknown | X31: 442 | Y31: YES | Z31: 642 | AA31: Overflow/Underflow
B32: Incorrect_Update_for_Loop_Iterator_2_NT.c | C32: NO | D32: 420 | E32: TIMEOUT | F32: 301407 | G32: NO | H32: 385 | I32: TRUE | J32: 4381 | K32: =IF(OR(E32="NO", E32="YES"), E32, IF(I32=FALSE, G32, E32)) -> TIMEOUT | L32: =IF(OR(E32="NO", E32="YES"), F32, IF(I32=FALSE, SUM(F32, J32, H32), SUM(F32, J32))) -> 305788 | M32: =IF(OR(C32="NO", C32="YES"), C32, IF(OR(K32="NO", K32="YES"), K32, C32)) -> NO | N32: =IF(OR(C32="NO", C32="YES"), D32, IF(OR(K32="NO", K32="YES"), SUM(D32, L32), SUM(D32, L32))) -> 420 | O32: FALSE | P32: 61966 | Q32: TIMEOUT | R32: 1210032 | S32: UNKNOWN | T32: 22863 | U32: ERROR | V32: 6712 | W32: unknown | X32: 432 | Y32: NO | Z32: 443 | AA32: Overflow/Underflow
B33: Incorrect_Update_for_Loop_Iterator_2_T.c | C33: YES | D33: 946 | E33: YES | F33: 11891 | G33: NO | H33: 387 | I33: TRUE | J33: 4422 | K33: =IF(OR(E33="NO", E33="YES"), E33, IF(I33=FALSE, G33, E33)) -> YES | L33: =IF(OR(E33="NO", E33="YES"), F33, IF(I33=FALSE, SUM(F33, J33, H33), SUM(F33, J33))) -> 11891 | M33: =IF(OR(C33="NO", C33="YES"), C33, IF(OR(K33="NO", K33="YES"), K33, C33)) -> YES | N33: =IF(OR(C33="NO", C33="YES"), D33, IF(OR(K33="NO", K33="YES"), SUM(D33, L33), SUM(D33, L33))) -> 946 | O33: TRUE | P33: 124469 | Q33: TIMEOUT | R33: 1210032 | S33: UNKNOWN | T33: 24955 | U33: TRUE | V33: 5708 | W33: yes | X33: 362 | Y33: NO | Z33: 582 | AA33: Overflow/Underflow
B34: Incorrect_Update_for_Loop_Iterator_3_NT.c | C34: NO | D34: 538 | E34: NO | F34: 6478 | G34: NO | H34: 388 | I34: FALSE | J34: 4528 | K34: =IF(OR(E34="NO", E34="YES"), E34, IF(I34=FALSE, G34, E34)) -> NO | L34: =IF(OR(E34="NO", E34="YES"), F34, IF(I34=FALSE, SUM(F34, J34, H34), SUM(F34, J34))) -> 6478 | M34: =IF(OR(C34="NO", C34="YES"), C34, IF(OR(K34="NO", K34="YES"), K34, C34)) -> NO | N34: =IF(OR(C34="NO", C34="YES"), D34, IF(OR(K34="NO", K34="YES"), SUM(D34, L34), SUM(D34, L34))) -> 538 | O34: FALSE | P34: 2056 | Q34: NO | R34: 8250 | S34: FALSE | T34: 2253 | U34: UNKNOWN | V34: 1201030 | W34: unknown | X34: 392 | Y34: NO | Z34: 414 | AA34: Overflow/Underflow
B35: Missing_Corner-case_Handling_1_NT.c | C35: NO | D35: 457 | E35: NO | F35: 2488 | G35: NO | H35: 392 | I35: TRUE | J35: 4476 | K35: =IF(OR(E35="NO", E35="YES"), E35, IF(I35=FALSE, G35, E35)) -> NO | L35: =IF(OR(E35="NO", E35="YES"), F35, IF(I35=FALSE, SUM(F35, J35, H35), SUM(F35, J35))) -> 2488 | M35: =IF(OR(C35="NO", C35="YES"), C35, IF(OR(K35="NO", K35="YES"), K35, C35)) -> NO | N35: =IF(OR(C35="NO", C35="YES"), D35, IF(OR(K35="NO", K35="YES"), SUM(D35, L35), SUM(D35, L35))) -> 457 | O35: FALSE | P35: 2081 | Q35: NO | R35: 9249 | S35: ERROR | T35: 6626 | U35: UNKNOWN | V35: 7997 | W35: unknown | X35: 457 | Y35: NO | Z35: 452
B36: Missing_Corner-case_Handling_1_T.c | C36: YES | D36: 549 | E36: YES | F36: 2484 | G36: YES | H36: 392 | I36: TRUE | J36: 4443 | K36: =IF(OR(E36="NO", E36="YES"), E36, IF(I36=FALSE, G36, E36)) -> YES | L36: =IF(OR(E36="NO", E36="YES"), F36, IF(I36=FALSE, SUM(F36, J36, H36), SUM(F36, J36))) -> 2484 | M36: =IF(OR(C36="NO", C36="YES"), C36, IF(OR(K36="NO", K36="YES"), K36, C36)) -> YES | N36: =IF(OR(C36="NO", C36="YES"), D36, IF(OR(K36="NO", K36="YES"), SUM(D36, L36), SUM(D36, L36))) -> 549 | O36: TRUE | P36: 192199 | Q36: YES | R36: 4988 | S36: TRUE | T36: 3001 | U36: TRUE | V36: 7922 | W36: unknown | X36: 455 | Y36: YES | Z36: 3454
B37: Missing_Corner-case_Handling_2_NT.c | C37: NO | D37: 514 | E37: ERROR | F37: 319 | G37: ERROR | H37: 263 | I37: UNKNOWN | J37: 31262 | K37: =IF(OR(E37="NO", E37="YES"), E37, IF(I37=FALSE, G37, E37)) -> ERROR | L37: =IF(OR(E37="NO", E37="YES"), F37, IF(I37=FALSE, SUM(F37, J37, H37), SUM(F37, J37))) -> 31581 | M37: =IF(OR(C37="NO", C37="YES"), C37, IF(OR(K37="NO", K37="YES"), K37, C37)) -> NO | N37: =IF(OR(C37="NO", C37="YES"), D37, IF(OR(K37="NO", K37="YES"), SUM(D37, L37), SUM(D37, L37))) -> 514 | O37: INCONCLUSIVE | P37: 156308 | Q37: MAYBE | R37: 2576 | S37: FALSE | T37: 2568 | U37: UNKNOWN | V37: 1201099 | W37: unknown | X37: 517 | Y37: NO | Z37: 670 | AA37: Bit Calculation
B38: Missing_Corner-case_Handling_2_T.c | C38: YES | D38: 532 | E38: ERROR | F38: 303 | G38: ERROR | H38: 331 | I38: TRUE | J38: 15971 | K38: =IF(OR(E38="NO", E38="YES"), E38, IF(I38=FALSE, G38, E38)) -> ERROR | L38: =IF(OR(E38="NO", E38="YES"), F38, IF(I38=FALSE, SUM(F38, J38, H38), SUM(F38, J38))) -> 16274 | M38: =IF(OR(C38="NO", C38="YES"), C38, IF(OR(K38="NO", K38="YES"), K38, C38)) -> YES | N38: =IF(OR(C38="NO", C38="YES"), D38, IF(OR(K38="NO", K38="YES"), SUM(D38, L38), SUM(D38, L38))) -> 532 | O38: TRUE | P38: 34583 | Q38: MAYBE | R38: 2615 | S38: TRUE | T38: 2878 | U38: UNKNOWN | V38: 1201019 | W38: yes | X38: 417 | Y38: NO | Z38: 616 | AA38: Bit Calculation
B39: Missing_Corner-case_Handling_3_NT.c | C39: TIMEOUT | D39: 600420 | E39: TIMEOUT | F39: 300800 | G39: TIMEOUT | H39: 270332 | I39: UNKNOWN | J39: 31205 | K39: =IF(OR(E39="NO", E39="YES"), E39, IF(I39=FALSE, G39, E39)) -> TIMEOUT | L39: =IF(OR(E39="NO", E39="YES"), F39, IF(I39=FALSE, SUM(F39, J39, H39), SUM(F39, J39))) -> 332005 | M39: =IF(OR(C39="NO", C39="YES"), C39, IF(OR(K39="NO", K39="YES"), K39, C39)) -> TIMEOUT | N39: =IF(OR(C39="NO", C39="YES"), D39, IF(OR(K39="NO", K39="YES"), SUM(D39, L39), SUM(D39, L39))) -> 932425 | O39: INCONCLUSIVE | P39: 301744 | Q39: MAYBE | R39: 3414 | S39: UNKNOWN | T39: 51521 | U39: UNKNOWN | V39: 8807 | W39: unknown | X39: 1398 | Y39: NO | Z39: 3374 | AA39: Two-Dimentional Array
B40: Missing_Corner-case_Handling_3_T.c | C40: TIMEOUT | D40: 600454 | E40: TIMEOUT | F40: 300826 | G40: YES | H40: 38902 | I40: TRUE | J40: 6725 | K40: =IF(OR(E40="NO", E40="YES"), E40, IF(I40=FALSE, G40, E40)) -> TIMEOUT | L40: =IF(OR(E40="NO", E40="YES"), F40, IF(I40=FALSE, SUM(F40, J40, H40), SUM(F40, J40))) -> 307551 | M40: =IF(OR(C40="NO", C40="YES"), C40, IF(OR(K40="NO", K40="YES"), K40, C40)) -> TIMEOUT | N40: =IF(OR(C40="NO", C40="YES"), D40, IF(OR(K40="NO", K40="YES"), SUM(D40, L40), SUM(D40, L40))) -> 908005 | O40: TRUE | P40: 182602 | Q40: MAYBE | R40: 3446 | S40: TRUE | T40: 15334 | U40: UNKNOWN | V40: 8787 | W40: yes | X40: 1204 | Y40: TIMEOUT | Z40: 1210030 | AA40: Two-Dimentional Array
...

Sheet Charts
B2: Tool | C2: Category | D2: TermCOMP | E2: Shi et al. | R2: Tool | S2: Category | T2: Shi et al.
B3: Athena | C3: correct | D3: =(COUNTIFS(TermCOMP!S:S,"", TermCOMP!C:C, "YES", TermCOMP!D:D, "YES") + COUNTIFS(TermCOMP!S:S,"", TermCOMP!C:C, "NO", TermCOMP!D:D, "NO")) / (828 - COUNTIF(TermCOMP!S:S,"unsafe")) -> 0.7627965 | E3: =(COUNTIFS(FSE!AB:AB,"", FSE!B:B, "*_T.c", FSE!M:M, "YES") + COUNTIFS(FSE!AB:AB,"", FSE!B:B, "*_NT.c", FSE!M:M, "NO")) / (117 - COUNTIF(FSE!AB:AB,"unsafe")) -> 0.60952381 | R3: Athena_BV | S3: correct | T3: =(COUNTIFS(FSE!AB:AB,"", FSE!B:B, "*_T.c", FSE!C:C, "YES") + COUNTIFS(FSE!AB:AB,"", FSE!B:B, "*_NT.c", FSE!C:C, "NO")) / (117 - COUNTIF(FSE!AB:AB,"unsafe")) -> 0.55238095
C4: wrong | D4: =(COUNTIFS(TermCOMP!S:S,"", TermCOMP!C:C, "YES", TermCOMP!D:D, "NO") + COUNTIFS(TermCOMP!S:S,"", TermCOMP!C:C, "NO", TermCOMP!D:D, "YES")) / (828 - COUNTIF(TermCOMP!S:S,"unsafe")) -> 0 | E4: =(COUNTIFS(FSE!AB:AB,"", FSE!B:B, "*_T.c", FSE!M:M, "NO") + COUNTIFS(FSE!AB:AB,"", FSE!B:B, "*_NT.c", FSE!M:M, "YES") ) / (117 - COUNTIF(FSE!AB:AB,"unsafe")) -> 0 | S4: wrong | T4: =(COUNTIFS(FSE!AB:AB,"", FSE!B:B, "*_T.c", FSE!C:C, "NO") + COUNTIFS(FSE!AB:AB,"", FSE!B:B, "*_NT.c", FSE!C:C, "YES") ) / (117 - COUNTIF(FSE!AB:AB,"unsafe")) -> 0
C5: unknown | D5: =COUNTIFS(TermCOMP!S:S,"", TermCOMP!D:D, "MAYBE") / (828 - COUNTIF(TermCOMP!S:S,"unsafe")) -> 0.12234707 | E5: =COUNTIFS(FSE!AB:AB,"", FSE!M:M, "MAYBE") / (117 - COUNTIF(FSE!AB:AB,"unsafe")) -> 0.22857143 | S5: unknown | T5: =COUNTIFS(FSE!AB:AB,"", FSE!C:C, "MAYBE") / (117 - COUNTIF(FSE!AB:AB,"unsafe")) -> 0.22857143
C6: timeout | D6: =COUNTIFS(TermCOMP!S:S,"", TermCOMP!D:D, "TIMEOUT") / (828 - COUNTIF(TermCOMP!S:S,"unsafe")) -> 0.10986267 | E6: =COUNTIFS(FSE!AB:AB,"", FSE!M:M, "TIMEOUT") / (117 - COUNTIF(FSE!AB:AB,"unsafe")) -> 0.16190476 | S6: timeout | T6: =COUNTIFS(FSE!AB:AB,"", FSE!C:C, "TIMEOUT") / (117 - COUNTIF(FSE!AB:AB,"unsafe")) -> 0.21904762
C7: error | D7: =(COUNTIFS(TermCOMP!S:S,"", TermCOMP!D:D, "ERROR") + COUNTIFS(TermCOMP!S:S,"", TermCOMP!D:D, "OOM ERROR")) / (828 - COUNTIF(TermCOMP!S:S,"unsafe")) -> 0.0049937578 | E7: =(COUNTIFS(FSE!AB:AB,"", FSE!M:M, "ERROR") + COUNTIFS(FSE!AB:AB,"", FSE!M:M, "OOM ERROR")) / (117 - COUNTIF(FSE!AB:AB,"unsafe")) -> 0 | S7: abort | T7: =COUNTIFS(FSE!AB:AB,"", FSE!C:C, "ERROR") / (117 - COUNTIF(FSE!AB:AB,"unsafe")) -> 0
B8: Proton | C8: correct | D8: =(COUNTIFS(TermCOMP!S:S,"", TermCOMP!C:C, "YES", TermCOMP!F:F, "TRUE") + COUNTIFS(TermCOMP!S:S,"", TermCOMP!C:C, "NO", TermCOMP!F:F, "FALSE")) / (828 - COUNTIF(TermCOMP!S:S,"unsafe")) -> 0.75905119 | E8: =(COUNTIFS(FSE!AB:AB,"", FSE!B:B, "*_T.c", FSE!O:O, "TRUE") + COUNTIFS(FSE!AB:AB,"", FSE!B:B, "*_NT.c", FSE!O:O, "FALSE")) / (117 - COUNTIF(FSE!AB:AB,"unsafe")) -> 0.66666667 | S8: error | T8: =COUNTIFS(FSE!AB:AB,"", FSE!C:C, "OOM ERROR") / (117 - COUNTIF(FSE!AB:AB,"unsafe")) -> 0
C9: wrong | D9: =(COUNTIFS(TermCOMP!S:S,"", TermCOMP!C:C, "YES", TermCOMP!F:F, "FALSE") + COUNTIFS(TermCOMP!S:S,"", TermCOMP!C:C, "NO", TermCOMP!F:F, "TRUE")) / (828 - COUNTIF(TermCOMP!S:S,"unsafe")) -> 0.073657928 | E9: =(COUNTIFS(FSE!AB:AB,"", FSE!B:B, "*_T.c", FSE!O:O, "FALSE") + COUNTIFS(FSE!AB:AB,"", FSE!B:B, "*_NT.c", FSE!O:O, "TRUE")) / (117 - COUNTIF(FSE!AB:AB,"unsafe")) -> 0.085714286 | R9: Athena_MA | S9: correct | T9: =(COUNTIFS(FSE!AB:AB,"", FSE!B:B, "*_T.c", FSE!K:K, "YES") + COUNTIFS(FSE!AB:AB,"", FSE!B:B, "*_NT.c", FSE!K:K, "NO")) / (117 - COUNTIF(FSE!AB:AB,"unsafe")) -> 0.44761905
C10: unknown | D10: =COUNTIFS(TermCOMP!S:S,"", TermCOMP!F:F, "INCONCLUSIVE") / (828 - COUNTIF(TermCOMP!S:S,"unsafe")) -> 0.16479401 | E10: =COUNTIFS(FSE!AB:AB,"", FSE!O:O, "INCONCLUSIVE") / (117 - COUNTIF(FSE!AB:AB,"unsafe")) -> 0.24761905 | S10: wrong | T10: =(COUNTIFS(FSE!AB:AB,"", FSE!B:B, "*_T.c", FSE!K:K, "NO") + COUNTIFS(FSE!AB:AB,"", FSE!B:B, "*_NT.c", FSE!K:K, "YES") ) / (117 - COUNTIF(FSE!AB:AB,"unsafe")) -> 0
C11: timeout | D11: =COUNTIFS(TermCOMP!S:S,"", TermCOMP!F:F, "Terminated") / (828 - COUNTIF(TermCOMP!S:S,"unsafe")) -> 0 | E11: =COUNTIFS(FSE!AB:AB,"", FSE!O:O, "Terminated") / (117 - COUNTIF(FSE!AB:AB,"unsafe")) -> 0 | S11: unknown | T11: =COUNTIFS(FSE!AB:AB,"", FSE!K:K, "MAYBE") / (117 - COUNTIF(FSE!AB:AB,"unsafe")) -> 0.22857143
C12: error | D12: =COUNTIFS(TermCOMP!S:S,"", TermCOMP!F:F, "INTERNAL-ERROR") / (828 - COUNTIF(TermCOMP!S:S,"unsafe")) -> 0.0012484395 | E12: =COUNTIFS(FSE!AB:AB,"", FSE!O:O, "INTERNAL-ERROR") / (117 - COUNTIF(FSE!AB:AB,"unsafe")) -> 0 | S12: timeout | T12: =COUNTIFS(FSE!AB:AB,"", FSE!K:K, "TIMEOUT") / (117 - COUNTIF(FSE!AB:AB,"unsafe")) -> 0.23809524
B13: AProVE | C13: correct | D13: =(COUNTIFS(TermCOMP!S:S,"", TermCOMP!C:C, "YES", TermCOMP!H:H, "YES") + COUNTIFS(TermCOMP!S:S,"", TermCOMP!C:C, "NO", TermCOMP!H:H, "NO")) / (828 - COUNTIF(TermCOMP!S:S,"unsafe")) -> 0.72908864 | E13: =(COUNTIFS(FSE!AB:AB,"", FSE!B:B, "*_T.c", FSE!Q:Q, "YES") + COUNTIFS(FSE!AB:AB,"", FSE!B:B, "*_NT.c", FSE!Q:Q, "NO")) / (117 - COUNTIF(FSE!AB:AB,"unsafe")) -> 0.35238095 | S13: abort | T13: =COUNTIFS(FSE!AB:AB,"", FSE!K:K, "ERROR") / (117 - COUNTIF(FSE!AB:AB,"unsafe")) -> 0.076190476
C14: wrong | D14: =(COUNTIFS(TermCOMP!S:S,"", TermCOMP!C:C, "YES", TermCOMP!H:H, "NO") + COUNTIFS(TermCOMP!S:S,"", TermCOMP!C:C, "NO", TermCOMP!H:H, "YES")) / (828 - COUNTIF(TermCOMP!S:S,"unsafe")) -> 0 | E14: =(COUNTIFS(FSE!AB:AB,"", FSE!B:B, "*_T.c", FSE!Q:Q, "NO") + COUNTIFS(FSE!AB:AB,"", FSE!B:B, "*_NT.c", FSE!Q:Q, "YES")) / (117 - COUNTIF(FSE!AB:AB,"unsafe")) -> 0.028571429 | S14: error | T14: =COUNTIFS(FSE!AB:AB,"", FSE!K:K, "OOM ERROR") / (117 - COUNTIF(FSE!AB:AB,"unsafe")) -> 0.0095238095
C15: unknown | D15: =COUNTIFS(TermCOMP!S:S,"", TermCOMP!H:H, "MAYBE") / (828 - COUNTIF(TermCOMP!S:S,"unsafe")) -> 0.10486891 | E15: =COUNTIFS(FSE!AB:AB,"", FSE!Q:Q, "MAYBE") / (117 - COUNTIF(FSE!AB:AB,"unsafe")) -> 0.54285714 | R15: Athena | S15: correct | T15: =(COUNTIFS(FSE!AB:AB,"", FSE!B:B, "*_T.c", FSE!M:M, "YES") + COUNTIFS(FSE!AB:AB,"", FSE!B:B, "*_NT.c", FSE!M:M, "NO")) / (117 - COUNTIF(FSE!AB:AB,"unsafe")) -> 0.60952381
C16: timeout | D16: =COUNTIFS(TermCOMP!S:S,"", TermCOMP!H:H, "TIMEOUT") / (828 - COUNTIF(TermCOMP!S:S,"unsafe")) -> 0.084893883 | E16: =COUNTIFS(FSE!AB:AB,"", FSE!Q:Q, "TIMEOUT") / (117 - COUNTIF(FSE!AB:AB,"unsafe")) -> 0.066666667 | S16: wrong | T16: =(COUNTIFS(FSE!AB:AB,"", FSE!B:B, "*_T.c", FSE!M:M, "NO") + COUNTIFS(FSE!AB:AB,"", FSE!B:B, "*_NT.c", FSE!M:M, "YES") ) / (117 - COUNTIF(FSE!AB:AB,"unsafe")) -> 0
C17: error | D17: =COUNTIFS(TermCOMP!S:S,"", TermCOMP!H:H, "ERROR") / (828 - COUNTIF(TermCOMP!S:S,"unsafe")) -> 0.081148564 | E17: =COUNTIFS(FSE!AB:AB,"", FSE!Q:Q, "ERROR") / (117 - COUNTIF(FSE!AB:AB,"unsafe")) -> 0.0095238095 | S17: unknown | T17: =COUNTIFS(FSE!AB:AB,"", FSE!M:M, "MAYBE") / (117 - COUNTIF(FSE!AB:AB,"unsafe")) -> 0.22857143
B18: UAutomizer | C18: correct | D18: =(COUNTIFS(TermCOMP!S:S,"", TermCOMP!C:C, "YES", TermCOMP!J:J, "TRUE") + COUNTIFS(TermCOMP!S:S,"", TermCOMP!C:C, "NO", TermCOMP!J:J, "FALSE")) / (828 - COUNTIF(TermCOMP!S:S,"unsafe")) -> 0.78651685 | E18: =(COUNTIFS(FSE!AB:AB,"", FSE!B:B, "*_T.c", FSE!S:S, "TRUE") + COUNTIFS(FSE!AB:AB,"", FSE!B:B, "*_NT.c", FSE!S:S, "FALSE")) / (117 - COUNTIF(FSE!AB:AB,"unsafe")) -> 0.43809524 | S18: timeout | T18: =COUNTIFS(FSE!AB:AB,"", FSE!M:M, "TIMEOUT") / (117 - COUNTIF(FSE!AB:AB,"unsafe")) -> 0.16190476
C19: wrong | D19: =(COUNTIFS(TermCOMP!S:S,"", TermCOMP!C:C, "YES", TermCOMP!J:J, "FALSE") + COUNTIFS(TermCOMP!S:S,"", TermCOMP!C:C, "NO", TermCOMP!J:J, "TRUE")) / (828 - COUNTIF(TermCOMP!S:S,"unsafe")) -> 0 | E19: =(COUNTIFS(FSE!AB:AB,"", FSE!B:B, "*_T.c", FSE!S:S, "FALSE") + COUNTIFS(FSE!AB:AB,"", FSE!B:B, "*_NT.c", FSE!S:S, "TRUE")) / (117 - COUNTIF(FSE!AB:AB,"unsafe")) -> 0 | S19: abort | T19: =COUNTIFS(FSE!AB:AB,"", FSE!M:M, "ERROR") / (117 - COUNTIF(FSE!AB:AB,"unsafe")) -> 0
C20: unknown | D20: =COUNTIFS(TermCOMP!S:S,"", TermCOMP!J:J, "UNKNOWN") / (828 - COUNTIF(TermCOMP!S:S,"unsafe")) -> 0.18476904 | E20: =COUNTIFS(FSE!AB:AB,"", FSE!S:S, "UNKNOWN") / (117 - COUNTIF(FSE!AB:AB,"unsafe")) -> 0.35238095 | S20: error | T20: =COUNTIFS(FSE!AB:AB,"", FSE!M:M, "OOM ERROR") / (117 - COUNTIF(FSE!AB:AB,"unsafe")) -> 0
C21: timeout | D21: =COUNTIFS(TermCOMP!S:S,"", TermCOMP!J:J, "TIMEOUT") / (828 - COUNTIF(TermCOMP!S:S,"unsafe")) -> 0 | E21: =COUNTIFS(FSE!AB:AB,"", FSE!S:S, "TIMEOUT") / (117 - COUNTIF(FSE!AB:AB,"unsafe")) -> 0.14285714
C22: error | D22: =COUNTIFS(TermCOMP!S:S,"", TermCOMP!J:J, "ERROR") / (828 - COUNTIF(TermCOMP!S:S,"unsafe")) -> 0.028714107 | E22: =COUNTIFS(FSE!AB:AB,"", FSE!S:S, "ERROR") / (117 - COUNTIF(FSE!AB:AB,"unsafe")) -> 0.066666667
B23: CPAchecker | C23: correct | D23: =(COUNTIFS(TermCOMP!S:S,"", TermCOMP!C:C, "YES", TermCOMP!L:L, "TRUE") + COUNTIFS(TermCOMP!S:S,"", TermCOMP!C:C, "NO", TermCOMP!L:L, "FALSE")) / (828 - COUNTIF(TermCOMP!S:S,"unsafe")) -> 0.31210986 | E23: =(COUNTIFS(FSE!AB:AB,"", FSE!B:B, "*_T.c", FSE!U:U, "TRUE") + COUNTIFS(FSE!AB:AB,"", FSE!B:B, "*_NT.c", FSE!U:U, "FALSE")) / (117 - COUNTIF(FSE!AB:AB,"unsafe")) -> 0.12380952
C24: wrong | D24: =(COUNTIFS(TermCOMP!S:S,"", TermCOMP!C:C, "YES", TermCOMP!L:L, "FALSE") + COUNTIFS(TermCOMP!S:S,"", TermCOMP!C:C, "NO", TermCOMP!L:L, "TRUE")) / (828 - COUNTIF(TermCOMP!S:S,"unsafe")) -> 0.0037453184 | E24: =(COUNTIFS(FSE!AB:AB,"", FSE!B:B, "*_T.c", FSE!U:U, "FALSE") + COUNTIFS(FSE!AB:AB,"", FSE!B:B, "*_NT.c", FSE!U:U, "TRUE")) / (117 - COUNTIF(FSE!AB:AB,"unsafe")) -> 0.038095238
C25: unknown | D25: =COUNTIFS(TermCOMP!S:S,"", TermCOMP!L:L, "UNKNOWN") / (828 - COUNTIF(TermCOMP!S:S,"unsafe")) -> 0.56928839 | E25: =COUNTIFS(FSE!AB:AB,"", FSE!U:U, "UNKNOWN") / (117 - COUNTIF(FSE!AB:AB,"unsafe")) -> 0.4952381
C26: timeout | D26: =COUNTIFS(TermCOMP!S:S,"", TermCOMP!L:L, "TIMEOUT") / (828 - COUNTIF(TermCOMP!S:S,"unsafe")) -> 0.028714107 | E26: =COUNTIFS(FSE!AB:AB,"", FSE!U:U, "TIMEOUT") / (117 - COUNTIF(FSE!AB:AB,"unsafe")) -> 0.038095238
C27: error | D27: =COUNTIFS(TermCOMP!S:S,"", TermCOMP!L:L, "ERROR") / (828 - COUNTIF(TermCOMP!S:S,"unsafe")) -> 0.086142322 | E27: =COUNTIFS(FSE!AB:AB,"", FSE!U:U, "ERROR") / (117 - COUNTIF(FSE!AB:AB,"unsafe")) -> 0.3047619
B28: 2LS | C28: correct | D28: =(COUNTIFS(TermCOMP!S:S,"", TermCOMP!C:C, "YES", TermCOMP!N:N, "yes") + COUNTIFS(TermCOMP!S:S,"", TermCOMP!C:C, "NO", TermCOMP!N:N, "no")) / (828 - COUNTIF(TermCOMP!S:S,"unsafe")) -> 0.32709114 | E28: =(COUNTIFS(FSE!AB:AB,"", FSE!B:B, "*_T.c", FSE!W:W, "yes") + COUNTIFS(FSE!AB:AB,"", FSE!B:B, "*_NT.c", FSE!W:W, "no")) / (117 - COUNTIF(FSE!AB:AB,"unsafe")) -> 0.22857143
C29: wrong | D29: =(COUNTIFS(TermCOMP!S:S,"", TermCOMP!C:C, "YES", TermCOMP!N:N, "no") + COUNTIFS(TermCOMP!S:S,"", TermCOMP!C:C, "NO", TermCOMP!N:N, "yes")) / (828 - COUNTIF(TermCOMP!S:S,"unsafe")) -> 0.019975031 | E29: =(COUNTIFS(FSE!AB:AB,"", FSE!B:B, "*_T.c", FSE!W:W, "no") + COUNTIFS(FSE!AB:AB,"", FSE!B:B, "*_NT.c", FSE!W:W, "yes")) / (117 - COUNTIF(FSE!AB:AB,"unsafe")) -> 0.019047619
C30: unknown | D30: =COUNTIFS(TermCOMP!S:S,"", TermCOMP!N:N, "unknown") / (828 - COUNTIF(TermCOMP!S:S,"unsafe")) -> 0.43945069 | E30: =COUNTIFS(FSE!AB:AB,"", FSE!W:W, "unknown") / (117 - COUNTIF(FSE!AB:AB,"unsafe")) -> 0.55238095
C31: timeout | D31: =COUNTIFS(TermCOMP!S:S,"", TermCOMP!N:N, "timeout") / (828 - COUNTIF(TermCOMP!S:S,"unsafe")) -> 0.012484395 | E31: =COUNTIFS(FSE!AB:AB,"", FSE!W:W, "timeout") / (117 - COUNTIF(FSE!AB:AB,"unsafe")) -> 0
C32: error | D32: =COUNTIFS(TermCOMP!S:S,"", TermCOMP!N:N, "error") / (828 - COUNTIF(TermCOMP!S:S,"unsafe")) -> 0.20099875 | E32: =COUNTIFS(FSE!AB:AB,"", FSE!W:W, "error") / (117 - COUNTIF(FSE!AB:AB,"unsafe")) -> 0.2
B33: MuVal | C33: correct | D33: =(COUNTIFS(TermCOMP!S:S,"", TermCOMP!C:C, "YES", TermCOMP!P:P, "YES") + COUNTIFS(TermCOMP!S:S,"", TermCOMP!C:C, "NO", TermCOMP!P:P, "NO")) / (828 - COUNTIF(TermCOMP!S:S,"unsafe")) -> 0.65667915 | E33: =(COUNTIFS(FSE!AB:AB,"", FSE!B:B, "*_T.c", FSE!Y:Y, "YES") + COUNTIFS(FSE!AB:AB,"", FSE!B:B, "*_NT.c", FSE!Y:Y, "NO")) / (117 - COUNTIF(FSE!AB:AB,"unsafe")) -> 0.60952381
C34: wrong | D34: =(COUNTIFS(TermCOMP!S:S,"", TermCOMP!C:C, "YES", TermCOMP!P:P, "NO") + COUNTIFS(TermCOMP!S:S,"", TermCOMP!C:C, "NO", TermCOMP!P:P, "YES")) / (828 - COUNTIF(TermCOMP!S:S,"unsafe")) -> 0.16853933 | E34: =(COUNTIFS(FSE!AB:AB,"", FSE!B:B, "*_T.c", FSE!Y:Y, "NO") + COUNTIFS(FSE!AB:AB,"", FSE!B:B, "*_NT.c", FSE!Y:Y, "YES")) / (117 - COUNTIF(FSE!AB:AB,"unsafe")) -> 0.21904762
C35: unknown | D35: =COUNTIFS(TermCOMP!S:S,"", TermCOMP!P:P, "MAYBE") / (828 - COUNTIF(TermCOMP!S:S,"unsafe")) -> 0 | E35: =COUNTIFS(FSE!AB:AB,"", FSE!Y:Y, "MAYBE") / (117 - COUNTIF(FSE!AB:AB,"unsafe")) -> 0
C36: timeout | D36: =COUNTIFS(TermCOMP!S:S,"", TermCOMP!P:P, "TIMEOUT") / (828 - COUNTIF(TermCOMP!S:S,"unsafe")) -> 0.049937578 | E36: =COUNTIFS(FSE!AB:AB,"", FSE!Y:Y, "TIMEOUT") / (117 - COUNTIF(FSE!AB:AB,"unsafe")) -> 0.057142857
C37: error | D37: =COUNTIFS(TermCOMP!S:S,"", TermCOMP!P:P, "ERROR") / (828 - COUNTIF(TermCOMP!S:S,"unsafe")) -> 0.12484395 | E37: =COUNTIFS(FSE!AB:AB,"", FSE!Y:Y, "ERROR") / (117 - COUNTIF(FSE!AB:AB,"unsafe")) -> 0.11428571
B41: TermCOMP
B42: Matric | C42: Athena | D42: Prototn | E42: AProVE | F42: UAutomizer | G42: CPAchecker | H42: 2LS | I42: MuVal
B43: Avg. Runtime | C43: =AVERAGEIF(TermCOMP!S:S, "", TermCOMP!E2:E829) / 1000 -> 105.609 | D43: =AVERAGEIF(TermCOMP!S:S, "", TermCOMP!G2:G829) / 1000 -> 114.50298 | E43: =AVERAGEIF(TermCOMP!S:S, "", TermCOMP!I2:I829) / 1000 -> 115.9188 | F43: =AVERAGEIF(TermCOMP!S:S, "", TermCOMP!K2:K829) / 1000 -> 96.343588 | G43: =AVERAGEIF(TermCOMP!S:S, "", TermCOMP!M2:M829) / 1000 -> 230.87328 | H43: =AVERAGEIF(TermCOMP!S:S, "", TermCOMP!O2:O829) / 1000 -> 17.616303 | I43: =AVERAGEIF(TermCOMP!S:S, "", TermCOMP!Q2:Q829) / 1000 -> 59.460017
B45: Shi et al.
...
